<?xml version="1.0" ?>
<robot name="polybot" xmlns:xacro="http://ros.org/wiki/xacro">

  <!-- ****************** ROBOT CONSTANTS *******************************  -->  
  <!-- Define the size of the robot's main chassis in meters -->
  <xacro:property name="base_width" value="0.34"/>
  <xacro:property name="base_length" value="0.50"/>
  <xacro:property name="base_height" value="0.01"/>
	
  <!-- Define the shape of the robot's two back wheels in meters -->
  <xacro:property name="wheel_radius" value="0.1"/>
  <xacro:property name="wheel_width" value="0.02"/>

  <!-- x-axis points forward, y-axis points to left, z-axis points upwards -->
  <!-- Define the gap between the wheel and chassis along y-axis in meters -->
  <xacro:property name="wheel_ygap" value="0.018"/>

  <!-- Position the wheels along the z-axis -->
  <xacro:property name="wheel_zoff" value="-0.05"/>

  <!-- Position the wheels along the x-axis -->
  <xacro:property name="wheel_xoff" value="0.08"/>

  <!-- Position the caster wheel along the x-axis -->
  <xacro:property name="caster_xoff" value="0.165"/>

  <!-- Define intertial property macros  -->
  <xacro:macro name="box_inertia" params="m w h d">
    <inertial>
      <origin xyz="0 0 0" rpy="${pi/2} 0 ${pi/2}"/>
      <mass value="${m}"/>
      <inertia ixx="${(m/12) * (h*h + d*d)}" ixy="0.0" ixz="0.0" iyy="${(m/12) * (w*w + d*d)}" iyz="0.0" izz="${(m/12) * (w*w + h*h)}"/>
    </inertial>
  </xacro:macro>

  <xacro:macro name="cylinder_inertia" params="m r h">
    <inertial>
      <origin xyz="0 0 0" rpy="${pi/2} 0 0" />
      <mass value="${m}"/>
      <inertia ixx="${(m/12) * (3*r*r + h*h)}" ixy = "0" ixz = "0" iyy="${(m/12) * (3*r*r + h*h)}" iyz = "0" izz="${(m/2) * (r*r)}"/>
    </inertial>
  </xacro:macro>

  <xacro:macro name="sphere_inertia" params="m r">
    <inertial>
      <mass value="${m}"/>
      <inertia ixx="${(2/5) * m * (r*r)}" ixy="0.0" ixz="0.0" iyy="${(2/5) * m * (r*r)}" iyz="0.0" izz="${(2/5) * m * (r*r)}"/>
    </inertial>
  </xacro:macro>

  <!-- ****************** ROBOT BASE FOOTPRINT ***************************  -->
  <!-- Define the center of the main robot chassis projected on the ground -->	
  <link name="base_footprint"/>

  <!-- The base footprint of the robot is located underneath the chassis -->
  <joint name="base_joint" type="fixed">
    <parent link="base_footprint"/>
    <child link="base_link" />
    <origin xyz="0.0 0.0 ${(wheel_radius+wheel_zoff)}" rpy="0 0 0"/>
  </joint>

  <!-- ********************** ROBOT BASE *********************************  -->
  <link name="base_link">
    <visual>
      <origin xyz="0 0 0" rpy="0 0 0"/>
      <geometry>
        <mesh filename="package://polybot_robot/meshes/Chassis.stl" scale="0.0015 0.0015 0.0015"/>
      </geometry>
      <material name="Black">
        <color rgba="${125/255} ${125/255} ${125/255} 1.0"/>
      </material>
    </visual>

    <collision>
      <geometry>
        <box size="${base_length} ${base_width} ${base_height}"/>
      </geometry>
    </collision>

    <xacro:box_inertia m="40.0" w="${base_width}" d="${base_length}" h="${base_height}"/>
    
  </link>

  <gazebo reference="base_link">
    <material>Gazebo/Black</material>
  </gazebo>


  <!-- *********************** DRIVE WHEELS ******************************  -->

  <!-- * * * RIGHT * * *  -->
  <link name="wheel_right">
      <visual>
        <origin xyz="0 0 0" rpy="0 1.5707963267949 1.5707963267949"/>
        <geometry>
            <cylinder radius="${wheel_radius}" length="${wheel_width}"/>
        </geometry>
        <material name="White">
          <color rgba="${255/255} ${255/255} ${255/255} 1.0"/>
        </material>
      </visual>
      
      <collision>
        <origin xyz="0 0 0" rpy="0 1.5707963267949 1.5707963267949"/>
        <geometry>
          <cylinder radius="${wheel_radius}" length="${wheel_width}"/>
        </geometry>
      </collision>
      
      <xacro:cylinder_inertia m="110.5" r="${wheel_radius}" h="${wheel_width}"/>
      
    </link>

    <!-- Connect the wheels to the base_link at the appropriate location, and 
         define a continuous joint to allow the wheels to freely rotate about
         an axis -->
    <joint name="right_wheel_hinge" type="revolute">
      <parent link="base_link"/>
      <child link="wheel_right"/>
      <origin xyz="${-1*wheel_xoff} ${-1*(base_width/2+wheel_ygap)} ${-wheel_zoff}" rpy="0 0 0"/>
      <limit upper="3.1415" lower="-3.1415" effort="30" velocity="5.0"/>
      <axis xyz="0 1 0"/>
    </joint>

  <!-- * * * LEFT * * *  -->

  <link name="wheel_left">
      <visual>
        <origin xyz="0 0 0" rpy="0 1.5707963267949 1.5707963267949"/>
        <geometry>
            <cylinder radius="${wheel_radius}" length="${wheel_width}"/>
        </geometry>
        <material name="White">
          <color rgba="${255/255} ${255/255} ${255/255} 1.0"/>
        </material>
      </visual>
      
      <collision>
        <origin xyz="0 0 0" rpy="0 1.5707963267949 1.5707963267949"/>
        <geometry>
          <cylinder radius="${wheel_radius}" length="${wheel_width}"/>
        </geometry>
      </collision>
      
      <xacro:cylinder_inertia m="110.5" r="${wheel_radius}" h="${wheel_width}"/>
      
    </link>

    <!-- Connect the wheels to the base_link at the appropriate location, and 
         define a continuous joint to allow the wheels to freely rotate about
         an axis -->
    <joint name="left_wheel_hinge" type="revolute">
      <parent link="base_link"/>
      <child link="wheel_left"/>
      <origin xyz="${-1*wheel_xoff} ${1*(base_width/2+wheel_ygap)} ${-wheel_zoff}" rpy="0 0 0"/>
      <limit upper="3.1415" lower="-3.1415" effort="30" velocity="5.0"/>
      <axis xyz="0 1 0"/>
    </joint>

  
  <!-- *********************** IMU SETUP *********************************  -->
  <!-- Each sensor must be attached to a link.                              --> 
  
  <joint name="imu_joint" type="fixed">
    <parent link="base_link"/>
    <child link="imu_link"/>
    <origin xyz="-0.10 0 0.05" rpy="0 0 0"/>
  </joint>

  <link name="imu_link"/>


  <!-- *********************** GPS SETUP **********************************  -->
  <joint name="gps_joint" type="fixed">
    <parent link="base_link"/>
    <child link="gps_link"/>
    <origin xyz="0.10 0 0.05" rpy="0 0 0"/>
  </joint>

  <link name="gps_link"/>

</robot>
